Workbook

Sheet Guide
B2: Beauty Consumer Goods – 5-Year P&L Business Plan Template
B4: How to use
B5: 1. Assumptions | C5: Enter your company name, first financial year and all drivers. Only edit yellow cells with blue text.
B6: 2. Revenue Build | C6: Calculates units × price by category, splits gross sales by channel, and deducts trade discounts, promotions and returns.
B7: 3. P&L | C7: Full income statement: net revenue → gross profit → EBITDA → EBIT → net profit. No inputs here.
B8: 4. Summary | C8: Headline KPIs and charts. Check the channel mix flag reads OK.
B10: Colour legend
B11: Blue text, yellow fill | C11: Input – edit these
B12: Black text | C12: Formula – do not overwrite
B13: Green text | C13: Link pulled from another sheet
B15: Example data
B16: Pre-filled values | C16: All inputs contain illustrative example values for a UK indie beauty brand (e.g. Skincare: 60,000 units in Year 1 at £32 RRP, £4.80 product + packaging cost per unit). Replace them with your own figures.
B18: Structure of the business
B19: Product categories | C19: Skincare, Haircare, Makeup / Colour Cosmetics, Fragrance, Body & Bath – rename on the Assumptions sheet labels if needed.
B20: Sales channels | C20: DTC e-commerce, Retail / wholesale, Online marketplaces, International distributors.
B22: Simplifications
B23: Tax | C23: Tax is charged only on positive profit; loss carry-forward is not modelled.
B24: Depreciation | C24: Straight-line on cumulative capex over the useful life (assumes life ≥ 5 years).
B25: Prices | C25: All figures exclude VAT.

Sheet Summary
A1: 5-Year Business Plan – Summary
A2: =Assumptions!C4&" | Beauty consumer goods | "&Assumptions!C5 -> [Your Company Ltd] | Beauty consumer goods | GBP (£)
A4: Key metrics | B4: Unit | C4: ="FY"&(Assumptions!$C$6+0) -> FY2027 | D4: ="FY"&(Assumptions!$C$6+1) -> FY2028 | E4: ="FY"&(Assumptions!$C$6+2) -> FY2029 | F4: ="FY"&(Assumptions!$C$6+3) -> FY2030 | G4: ="FY"&(Assumptions!$C$6+4) -> FY2031
A5: Net revenue | B5: £ | C5: ='P&L'!C10 -> 3305262.5 | D5: ='P&L'!D10 -> 4636578 | E5: ='P&L'!E10 -> 6239236.4 | F5: ='P&L'!F10 -> 7649595.9 | G5: ='P&L'!G10 -> 9300585
A6: Net revenue growth % | B6: % | D6: ='P&L'!D11 -> 0.4027866 | E6: ='P&L'!E11 -> 0.34565546 | F6: ='P&L'!F11 -> 0.2260468 | G6: ='P&L'!G11 -> 0.21582697
A7: Gross profit | B7: £ | C7: ='P&L'!C20 -> 2134578.4 | D7: ='P&L'!D20 -> 2997539.5 | E7: ='P&L'!E20 -> 4127735.1 | F7: ='P&L'!F20 -> 5057259.1 | G7: ='P&L'!G20 -> 6155981.6
A8: Gross margin % | B8: % | C8: ='P&L'!C21 -> 0.64581206 | D8: ='P&L'!D21 -> 0.64649824 | E8: ='P&L'!E21 -> 0.66157696 | F8: ='P&L'!F21 -> 0.66111454 | G8: ='P&L'!G21 -> 0.66189187
A9: Total operating expenses | B9: £ | C9: ='P&L'!C54 -> 1742736.4 | D9: ='P&L'!D54 -> 2315917.3 | E9: ='P&L'!E54 -> 3062080.5 | F9: ='P&L'!F54 -> 3719654.4 | G9: ='P&L'!G54 -> 4186775.3
A10: EBITDA | B10: £ | C10: ='P&L'!C56 -> 391842.03 | D10: ='P&L'!D56 -> 681622.16 | E10: ='P&L'!E56 -> 1065654.6 | F10: ='P&L'!F56 -> 1337604.7 | G10: ='P&L'!G56 -> 1969206.3
A11: EBITDA margin % | B11: % | C11: ='P&L'!C57 -> 0.11855095 | D11: ='P&L'!D57 -> 0.14700975 | E11: ='P&L'!E57 -> 0.17079887 | F11: ='P&L'!F57 -> 0.17485952 | G11: ='P&L'!G57 -> 0.2117293
A12: Net profit / (loss) | B12: £ | C12: ='P&L'!C63 -> 273631.52 | D12: ='P&L'!D63 -> 484966.62 | E12: ='P&L'!E63 -> 763240.92 | F12: ='P&L'!F63 -> 960453.49 | G12: ='P&L'!G63 -> 1424404.7
A13: Net margin % | B13: % | C13: ='P&L'!C64 -> 0.082786622 | D13: ='P&L'!D64 -> 0.10459581 | E13: ='P&L'!E64 -> 0.12232922 | F13: ='P&L'!F64 -> 0.12555611 | G13: ='P&L'!G64 -> 0.15315217
A14: Cumulative net profit / (loss) | B14: £ | C14: ='P&L'!C65 -> 273631.52 | D14: ='P&L'!D65 -> 758598.14 | E14: ='P&L'!E65 -> 1521839.1 | F14: ='P&L'!F65 -> 2482292.6 | G14: ='P&L'!G65 -> 3906697.3
A15: Headcount (FTE) | B15: FTE | C15: ='P&L'!C41 -> 8 | D15: ='P&L'!D41 -> 12 | E15: ='P&L'!E41 -> 18 | F15: ='P&L'!F41 -> 23 | G15: ='P&L'!G41 -> 26
A16: Total units sold | B16: units | C16: ='Revenue Build'!C11 -> 184000 | D16: ='Revenue Build'!D11 -> 257250 | E16: ='Revenue Build'!E11 -> 339225 | F16: ='Revenue Build'!F11 -> 418996.25 | G16: ='Revenue Build'!G11 -> 496848
A17: Net revenue per unit | B17: £/unit | C17: =IFERROR('P&L'!C10/'Revenue Build'!C11,0) -> 17.963383 | D17: =IFERROR('P&L'!D10/'Revenue Build'!D11,0) -> 18.023627 | E17: =IFERROR('P&L'!E10/'Revenue Build'!E11,0) -> 18.39262 | F17: =IFERROR('P&L'!F10/'Revenue Build'!F11,0) -> 18.256956 | G17: =IFERROR('P&L'!G10/'Revenue Build'!G11,0) -> 18.719176
A18: Channel mix check (should be 100%) | B18: % | C18: =Assumptions!C34 -> 1 | D18: =Assumptions!D34 -> 1 | E18: =Assumptions!E34 -> 1 | F18: =Assumptions!F34 -> 1 | G18: =Assumptions!G34 -> 1 | H18: =IF(SUMPRODUCT(--(ROUND(Assumptions!C34:G34,4)<>1))=0,"OK","CHECK CHANNEL MIX") -> OK

Sheet Assumptions
A1: Beauty Consumer Goods Co. – Key Assumptions
A2: All inputs for the 5-year P&L. Edit yellow cells with blue text only; everything else calculates.
A4: Company name | C4: [Your Company Ltd]
A5: Currency | C5: GBP (£)
A6: First financial year (FY) | C6: 2027 | H6: Year label of the first forecast year; all headers update from this.
B8: Unit | C8: ="FY"&(Assumptions!$C$6+0) -> FY2027 | D8: ="FY"&(Assumptions!$C$6+1) -> FY2028 | E8: ="FY"&(Assumptions!$C$6+2) -> FY2029 | F8: ="FY"&(Assumptions!$C$6+3) -> FY2030 | G8: ="FY"&(Assumptions!$C$6+4) -> FY2031 | H8: Notes / source
A9: 1. Volume – units sold
A10: Skincare – units (Year 1) | B10: units | C10: 70000 | H10: Year 1 unit volume. Example value – replace with your own forecast.
A11: Skincare – unit growth % | B11: % | D11: 0.45 | E11: 0.35 | F11: 0.25 | G11: 0.2 | H11: YoY growth in units sold (Years 2–5).
A12: Haircare – units (Year 1) | B12: units | C12: 35000 | H12: Year 1 unit volume. Example value – replace with your own forecast.
A13: Haircare – unit growth % | B13: % | D13: 0.4 | E13: 0.3 | F13: 0.25 | G13: 0.2 | H13: YoY growth in units sold (Years 2–5).
A14: Makeup / Colour Cosmetics – units (Year 1) | B14: units | C14: 45000 | H14: Year 1 unit volume. Example value – replace with your own forecast.
A15: Makeup / Colour Cosmetics – unit growth % | B15: % | D15: 0.35 | E15: 0.3 | F15: 0.2 | G15: 0.15 | H15: YoY growth in units sold (Years 2–5).
A16: Fragrance – units (Year 1) | B16: units | C16: 9000 | H16: Year 1 unit volume. Example value – replace with your own forecast.
A17: Fragrance – unit growth % | B17: % | D17: 0.5 | E17: 0.4 | F17: 0.3 | G17: 0.25 | H17: YoY growth in units sold (Years 2–5).
A18: Body & Bath – units (Year 1) | B18: units | C18: 25000 | H18: Year 1 unit volume. Example value – replace with your own forecast.
A19: Body & Bath – unit growth % | B19: % | D19: 0.3 | E19: 0.25 | F19: 0.2 | G19: 0.15 | H19: YoY growth in units sold (Years 2–5).
A21: 2. Pricing – average retail price (RRP, ex-VAT)
A22: Skincare – avg RRP (Year 1) | B22: £/unit | C22: 32 | H22: Average selling price to consumer, excluding VAT.
A23: Haircare – avg RRP (Year 1) | B23: £/unit | C23: 18 | H23: Average selling price to consumer, excluding VAT.
A24: Makeup / Colour Cosmetics – avg RRP (Year 1) | B24: £/unit | C24: 22 | H24: Average selling price to consumer, excluding VAT.
A25: Fragrance – avg RRP (Year 1) | B25: £/unit | C25: 55 | H25: Average selling price to consumer, excluding VAT.
A26: Body & Bath – avg RRP (Year 1) | B26: £/unit | C26: 14 | H26: Average selling price to consumer, excluding VAT.
A27: Annual price increase | B27: % | D27: 0.03 | E27: 0.03 | F27: 0.03 | G27: 0.03 | H27: Applied to all categories' RRP from Year 2.
A29: 3. Channel mix & channel economics
A30: DTC – own e-commerce – % of gross sales | B30: % | C30: 0.55 | D30: 0.5 | E30: 0.45 | F30: 0.4 | G30: 0.38 | H30: Share of gross sales (at RRP) by channel. Must total 100% each year.
A31: Retail / wholesale – % of gross sales | B31: % | C31: 0.25 | D31: 0.28 | E31: 0.3 | F31: 0.32 | G31: 0.32 | H31: Share of gross sales (at RRP) by channel. Must total 100% each year.
A32: Online marketplaces (e.g. Amazon) – % of gross sales | B32: % | C32: 0.15 | D32: 0.15 | E32: 0.15 | F32: 0.15 | G32: 0.15 | H32: Share of gross sales (at RRP) by channel. Must total 100% each year.
A33: International distributors – % of gross sales | B33: % | C33: 0.05 | D33: 0.07 | E33: 0.1 | F33: 0.13 | G33: 0.15 | H33: Share of gross sales (at RRP) by channel. Must total 100% each year.
A34: Check: channel mix total | B34: % | C34: =SUM(C30:C33) -> 1 | D34: =SUM(D30:D33) -> 1 | E34: =SUM(E30:E33) -> 1 | F34: =SUM(F30:F33) -> 1 | G34: =SUM(G30:G33) -> 1 | H34: Should equal 100.0%.
A35: DTC – own e-commerce – trade discount off RRP | B35: % | C35: 0 | D35: 0 | E35: 0 | F35: 0 | G35: 0 | H35: Margin given to retailer / marketplace fee / distributor margin. 0% for own DTC.
A36: Retail / wholesale – trade discount off RRP | B36: % | C36: 0.5 | D36: 0.5 | E36: 0.5 | F36: 0.5 | G36: 0.5 | H36: Margin given to retailer / marketplace fee / distributor margin. 0% for own DTC.
A37: Online marketplaces (e.g. Amazon) – trade discount off RRP | B37: % | C37: 0.15 | D37: 0.15 | E37: 0.15 | F37: 0.15 | G37: 0.15 | H37: Margin given to retailer / marketplace fee / distributor margin. 0% for own DTC.
A38: International distributors – trade discount off RRP | B38: % | C38: 0.6 | D38: 0.6 | E38: 0.6 | F38: 0.6 | G38: 0.6 | H38: Margin given to retailer / marketplace fee / distributor margin. 0% for own DTC.
A39: Promotions & discounts (all channels) | B39: % gross | C39: 0.08 | D39: 0.08 | E39: 0.07 | F39: 0.07 | G39: 0.07 | H39: Promo codes, gift-with-purchase, retailer promo funding.
A40: Returns & refunds | B40: % gross | C40: 0.04 | D40: 0.04 | E40: 0.035 | F40: 0.035 | G40: 0.03 | H40: Customer returns, damages and refunds.
A42: 4. Cost of goods sold (per unit, Year 1)
A43: Skincare – formulation / product cost | B43: £/unit | C43: 3.6 | H43: Contract manufacturer price incl. fill. Year 1.
A44: Haircare – formulation / product cost | B44: £/unit | C44: 2 | H44: Contract manufacturer price incl. fill. Year 1.
A45: Makeup / Colour Cosmetics – formulation / product cost | B45: £/unit | C45: 2.6 | H45: Contract manufacturer price incl. fill. Year 1.
...

Sheet Revenue Build
A1: Revenue & COGS Build
A2: Volume × price by category, then channel deductions. All calculated – do not edit.
B4: Unit | C4: ="FY"&(Assumptions!$C$6+0) -> FY2027 | D4: ="FY"&(Assumptions!$C$6+1) -> FY2028 | E4: ="FY"&(Assumptions!$C$6+2) -> FY2029 | F4: ="FY"&(Assumptions!$C$6+3) -> FY2030 | G4: ="FY"&(Assumptions!$C$6+4) -> FY2031 | H4: Notes / source
A5: Units sold
A6: Skincare | B6: units | C6: =Assumptions!$C$10 -> 70000 | D6: =C6*(1+Assumptions!D11) -> 101500 | E6: =D6*(1+Assumptions!E11) -> 137025 | F6: =E6*(1+Assumptions!F11) -> 171281.25 | G6: =F6*(1+Assumptions!G11) -> 205537.5
A7: Haircare | B7: units | C7: =Assumptions!$C$12 -> 35000 | D7: =C7*(1+Assumptions!D13) -> 49000 | E7: =D7*(1+Assumptions!E13) -> 63700 | F7: =E7*(1+Assumptions!F13) -> 79625 | G7: =F7*(1+Assumptions!G13) -> 95550
A8: Makeup / Colour Cosmetics | B8: units | C8: =Assumptions!$C$14 -> 45000 | D8: =C8*(1+Assumptions!D15) -> 60750 | E8: =D8*(1+Assumptions!E15) -> 78975 | F8: =E8*(1+Assumptions!F15) -> 94770 | G8: =F8*(1+Assumptions!G15) -> 108985.5
A9: Fragrance | B9: units | C9: =Assumptions!$C$16 -> 9000 | D9: =C9*(1+Assumptions!D17) -> 13500 | E9: =D9*(1+Assumptions!E17) -> 18900 | F9: =E9*(1+Assumptions!F17) -> 24570 | G9: =F9*(1+Assumptions!G17) -> 30712.5
A10: Body & Bath | B10: units | C10: =Assumptions!$C$18 -> 25000 | D10: =C10*(1+Assumptions!D19) -> 32500 | E10: =D10*(1+Assumptions!E19) -> 40625 | F10: =E10*(1+Assumptions!F19) -> 48750 | G10: =F10*(1+Assumptions!G19) -> 56062.5
A11: Total units | B11: units | C11: =SUM(C6:C10) -> 184000 | D11: =SUM(D6:D10) -> 257250 | E11: =SUM(E6:E10) -> 339225 | F11: =SUM(F6:F10) -> 418996.25 | G11: =SUM(G6:G10) -> 496848
A13: Average RRP (ex-VAT)
A14: Skincare | B14: £/unit | C14: =Assumptions!$C$22 -> 32 | D14: =C14*(1+Assumptions!D27) -> 32.96 | E14: =D14*(1+Assumptions!E27) -> 33.9488 | F14: =E14*(1+Assumptions!F27) -> 34.967264 | G14: =F14*(1+Assumptions!G27) -> 36.016282
A15: Haircare | B15: £/unit | C15: =Assumptions!$C$23 -> 18 | D15: =C15*(1+Assumptions!D27) -> 18.54 | E15: =D15*(1+Assumptions!E27) -> 19.0962 | F15: =E15*(1+Assumptions!F27) -> 19.669086 | G15: =F15*(1+Assumptions!G27) -> 20.259159
A16: Makeup / Colour Cosmetics | B16: £/unit | C16: =Assumptions!$C$24 -> 22 | D16: =C16*(1+Assumptions!D27) -> 22.66 | E16: =D16*(1+Assumptions!E27) -> 23.3398 | F16: =E16*(1+Assumptions!F27) -> 24.039994 | G16: =F16*(1+Assumptions!G27) -> 24.761194
A17: Fragrance | B17: £/unit | C17: =Assumptions!$C$25 -> 55 | D17: =C17*(1+Assumptions!D27) -> 56.65 | E17: =D17*(1+Assumptions!E27) -> 58.3495 | F17: =E17*(1+Assumptions!F27) -> 60.099985 | G17: =F17*(1+Assumptions!G27) -> 61.902985
A18: Body & Bath | B18: £/unit | C18: =Assumptions!$C$26 -> 14 | D18: =C18*(1+Assumptions!D27) -> 14.42 | E18: =D18*(1+Assumptions!E27) -> 14.8526 | F18: =E18*(1+Assumptions!F27) -> 15.298178 | G18: =F18*(1+Assumptions!G27) -> 15.757123
A20: Gross sales at RRP
A21: Skincare | B21: £ | C21: =C6*C14 -> 2240000 | D21: =D6*D14 -> 3345440 | E21: =E6*E14 -> 4651834.3 | F21: =F6*F14 -> 5989236.7 | G21: =G6*G14 -> 7402696.5
A22: Haircare | B22: £ | C22: =C7*C15 -> 630000 | D22: =D7*D15 -> 908460 | E22: =E7*E15 -> 1216427.9 | F22: =F7*F15 -> 1566151 | G22: =G7*G15 -> 1935762.6
A23: Makeup / Colour Cosmetics | B23: £ | C23: =C8*C16 -> 990000 | D23: =D8*D16 -> 1376595 | E23: =E8*E16 -> 1843260.7 | F23: =F8*F16 -> 2278270.2 | G23: =G8*G16 -> 2698611.1
A24: Fragrance | B24: £ | C24: =C9*C17 -> 495000 | D24: =D9*D17 -> 764775 | E24: =E9*E17 -> 1102805.6 | F24: =F9*F17 -> 1476656.6 | G24: =G9*G17 -> 1901195.4
A25: Body & Bath | B25: £ | C25: =C10*C18 -> 350000 | D25: =D10*D18 -> 468650 | E25: =E10*E18 -> 603386.88 | F25: =F10*F18 -> 745786.18 | G25: =G10*G18 -> 883383.73
A26: Total gross sales | B26: £ | C26: =SUM(C21:C25) -> 4705000 | D26: =SUM(D21:D25) -> 6863920 | E26: =SUM(E21:E25) -> 9417715.4 | F26: =SUM(F21:F25) -> 12056101 | G26: =SUM(G21:G25) -> 14821649
A28: Gross sales by channel
A29: DTC – own e-commerce | B29: £ | C29: =C26*Assumptions!C30 -> 2587750 | D29: =D26*Assumptions!D30 -> 3431960 | E29: =E26*Assumptions!E30 -> 4237971.9 | F29: =F26*Assumptions!F30 -> 4822440.3 | G29: =G26*Assumptions!G30 -> 5632226.8
A30: Retail / wholesale | B30: £ | C30: =C26*Assumptions!C31 -> 1176250 | D30: =D26*Assumptions!D31 -> 1921897.6 | E30: =E26*Assumptions!E31 -> 2825314.6 | F30: =F26*Assumptions!F31 -> 3857952.2 | G30: =G26*Assumptions!G31 -> 4742927.8
A31: Online marketplaces (e.g. Amazon) | B31: £ | C31: =C26*Assumptions!C32 -> 705750 | D31: =D26*Assumptions!D32 -> 1029588 | E31: =E26*Assumptions!E32 -> 1412657.3 | F31: =F26*Assumptions!F32 -> 1808415.1 | G31: =G26*Assumptions!G32 -> 2223247.4
A32: International distributors | B32: £ | C32: =C26*Assumptions!C33 -> 235250 | D32: =D26*Assumptions!D33 -> 480474.4 | E32: =E26*Assumptions!E33 -> 941771.54 | F32: =F26*Assumptions!F33 -> 1567293.1 | G32: =G26*Assumptions!G33 -> 2223247.4
A34: Trade discounts by channel
A35: DTC – own e-commerce | B35: £ | C35: =C29*Assumptions!C35 -> 0 | D35: =D29*Assumptions!D35 -> 0 | E35: =E29*Assumptions!E35 -> 0 | F35: =F29*Assumptions!F35 -> 0 | G35: =G29*Assumptions!G35 -> 0
A36: Retail / wholesale | B36: £ | C36: =C30*Assumptions!C36 -> 588125 | D36: =D30*Assumptions!D36 -> 960948.8 | E36: =E30*Assumptions!E36 -> 1412657.3 | F36: =F30*Assumptions!F36 -> 1928976.1 | G36: =G30*Assumptions!G36 -> 2371463.9
A37: Online marketplaces (e.g. Amazon) | B37: £ | C37: =C31*Assumptions!C37 -> 105862.5 | D37: =D31*Assumptions!D37 -> 154438.2 | E37: =E31*Assumptions!E37 -> 211898.6 | F37: =F31*Assumptions!F37 -> 271262.27 | G37: =G31*Assumptions!G37 -> 333487.11
A38: International distributors | B38: £ | C38: =C32*Assumptions!C38 -> 141150 | D38: =D32*Assumptions!D38 -> 288284.64 | E38: =E32*Assumptions!E38 -> 565062.92 | F38: =F32*Assumptions!F38 -> 940375.85 | G38: =G32*Assumptions!G38 -> 1333948.4
A39: Total trade discounts | B39: £ | C39: =SUM(C35:C38) -> 835137.5 | D39: =SUM(D35:D38) -> 1403671.6 | E39: =SUM(E35:E38) -> 2189618.8 | F39: =SUM(F35:F38) -> 3140614.2 | G39: =SUM(G35:G38) -> 4038899.5
A41: Net revenue by channel (after trade discount, promotions & returns)
A42: DTC – own e-commerce | B42: £ | C42: =C29-C35-C29*(Assumptions!C39+Assumptions!C40) -> 2277220 | D42: =D29-D35-D29*(Assumptions!D39+Assumptions!D40) -> 3020124.8 | E42: =E29-E35-E29*(Assumptions!E39+Assumptions!E40) -> 3792984.9 | F42: =F29-F35-F29*(Assumptions!F39+Assumptions!F40) -> 4316084.1 | G42: =G29-G35-G29*(Assumptions!G39+Assumptions!G40) -> 5069004.1
A43: Retail / wholesale | B43: £ | C43: =C30-C36-C30*(Assumptions!C39+Assumptions!C40) -> 446975 | D43: =D30-D36-D30*(Assumptions!D39+Assumptions!D40) -> 730321.09 | E43: =E30-E36-E30*(Assumptions!E39+Assumptions!E40) -> 1115999.3 | F43: =F30-F36-F30*(Assumptions!F39+Assumptions!F40) -> 1523891.1 | G43: =G30-G36-G30*(Assumptions!G39+Assumptions!G40) -> 1897171.1
A44: Online marketplaces (e.g. Amazon) | B44: £ | C44: =C31-C37-C31*(Assumptions!C39+Assumptions!C40) -> 515197.5 | D44: =D31-D37-D31*(Assumptions!D39+Assumptions!D40) -> 751599.24 | E44: =E31-E37-E31*(Assumptions!E39+Assumptions!E40) -> 1052429.7 | F44: =F31-F37-F31*(Assumptions!F39+Assumptions!F40) -> 1347269.3 | G44: =G31-G37-G31*(Assumptions!G39+Assumptions!G40) -> 1667435.6
A45: International distributors | B45: £ | C45: =C32-C38-C32*(Assumptions!C39+Assumptions!C40) -> 65870 | D45: =D32-D38-D32*(Assumptions!D39+Assumptions!D40) -> 134532.83 | E45: =E32-E38-E32*(Assumptions!E39+Assumptions!E40) -> 277822.6 | F45: =F32-F38-F32*(Assumptions!F39+Assumptions!F40) -> 462351.46 | G45: =G32-G38-G32*(Assumptions!G39+Assumptions!G40) -> 666974.22
A46: Total net revenue | B46: £ | C46: =SUM(C42:C45) -> 3305262.5 | D46: =SUM(D42:D45) -> 4636578 | E46: =SUM(E42:E45) -> 6239236.4 | F46: =SUM(F42:F45) -> 7649595.9 | G46: =SUM(G42:G45) -> 9300585
...

Sheet P&L
A1: 5-Year Profit & Loss Statement
A2: £, financial years. Fully calculated from Assumptions and Revenue Build.
A4: £ | B4: Unit | C4: ="FY"&(Assumptions!$C$6+0) -> FY2027 | D4: ="FY"&(Assumptions!$C$6+1) -> FY2028 | E4: ="FY"&(Assumptions!$C$6+2) -> FY2029 | F4: ="FY"&(Assumptions!$C$6+3) -> FY2030 | G4: ="FY"&(Assumptions!$C$6+4) -> FY2031 | H4: Notes / source
A5: Revenue
A6: Gross sales (at RRP) | B6: £ | C6: ='Revenue Build'!C26 -> 4705000 | D6: ='Revenue Build'!D26 -> 6863920 | E6: ='Revenue Build'!E26 -> 9417715.4 | F6: ='Revenue Build'!F26 -> 12056101 | G6: ='Revenue Build'!G26 -> 14821649
A7: Less: trade discounts & channel margins | B7: £ | C7: =-'Revenue Build'!C39 -> -835137.5 | D7: =-'Revenue Build'!D39 -> -1403671.6 | E7: =-'Revenue Build'!E39 -> -2189618.8 | F7: =-'Revenue Build'!F39 -> -3140614.2 | G7: =-'Revenue Build'!G39 -> -4038899.5
A8: Less: promotions & discounts | B8: £ | C8: =-C6*Assumptions!C39 -> -376400 | D8: =-D6*Assumptions!D39 -> -549113.6 | E8: =-E6*Assumptions!E39 -> -659240.08 | F8: =-F6*Assumptions!F39 -> -843927.05 | G8: =-G6*Assumptions!G39 -> -1037515.5
A9: Less: returns & refunds | B9: £ | C9: =-C6*Assumptions!C40 -> -188200 | D9: =-D6*Assumptions!D40 -> -274556.8 | E9: =-E6*Assumptions!E40 -> -329620.04 | F9: =-F6*Assumptions!F40 -> -421963.52 | G9: =-G6*Assumptions!G40 -> -444649.48
A10: Net revenue | B10: £ | C10: =SUM(C6:C9) -> 3305262.5 | D10: =SUM(D6:D9) -> 4636578 | E10: =SUM(E6:E9) -> 6239236.4 | F10: =SUM(F6:F9) -> 7649595.9 | G10: =SUM(G6:G9) -> 9300585
A11: Net revenue growth % | B11: % | D11: =IFERROR(D10/C10-1,0) -> 0.4027866 | E11: =IFERROR(E10/D10-1,0) -> 0.34565546 | F11: =IFERROR(F10/E10-1,0) -> 0.2260468 | G11: =IFERROR(G10/F10-1,0) -> 0.21582697
A13: Cost of sales
A14: Product & packaging COGS | B14: £ | C14: ='Revenue Build'!C61 -> 741000 | D14: ='Revenue Build'!D61 -> 1059466.2 | E14: ='Revenue Build'!E61 -> 1425185.4 | F14: ='Revenue Build'!F61 -> 1789129.3 | G14: ='Revenue Build'!G61 -> 2168041.9
A15: Inbound freight & duties | B15: £ | C15: =Assumptions!C55*C10 -> 132210.5 | D15: =Assumptions!D55*D10 -> 185463.12 | E15: =Assumptions!E55*E10 -> 218373.28 | F15: =Assumptions!F55*F10 -> 267735.86 | G15: =Assumptions!G55*G10 -> 325520.47
A16: Warehousing & fulfilment | B16: £ | C16: =Assumptions!C56*C10 -> 231368.38 | D16: =Assumptions!D56*D10 -> 301377.57 | E16: =Assumptions!E56*E10 -> 374354.19 | F16: =Assumptions!F56*F10 -> 420727.77 | G16: =Assumptions!G56*G10 -> 511532.17
A17: Inventory write-offs | B17: £ | C17: =Assumptions!C57*C10 -> 66105.25 | D17: =Assumptions!D57*D10 -> 92731.559 | E17: =Assumptions!E57*E10 -> 93588.547 | F17: =Assumptions!F57*F10 -> 114743.94 | G17: =Assumptions!G57*G10 -> 139508.77
A18: Total cost of sales | B18: £ | C18: =SUM(C14:C17) -> 1170684.1 | D18: =SUM(D14:D17) -> 1639038.5 | E18: =SUM(E14:E17) -> 2111501.4 | F18: =SUM(F14:F17) -> 2592336.8 | G18: =SUM(G14:G17) -> 3144603.4
A20: Gross profit | B20: £ | C20: =C10-C18 -> 2134578.4 | D20: =D10-D18 -> 2997539.5 | E20: =E10-E18 -> 4127735.1 | F20: =F10-F18 -> 5057259.1 | G20: =G10-G18 -> 6155981.6
A21: Gross margin % | B21: % | C21: =IFERROR(C20/C10,0) -> 0.64581206 | D21: =IFERROR(D20/D10,0) -> 0.64649824 | E21: =IFERROR(E20/E10,0) -> 0.66157696 | F21: =IFERROR(F20/F10,0) -> 0.66111454 | G21: =IFERROR(G20/G10,0) -> 0.66189187
A23: Marketing & selling
A24: Performance / digital advertising | B24: £ | C24: =Assumptions!C60*C10 -> 528842 | D24: =Assumptions!D60*D10 -> 649120.91 | E24: =Assumptions!E60*E10 -> 748708.37 | F24: =Assumptions!F60*F10 -> 841455.55 | G24: =Assumptions!G60*G10 -> 930058.5
A25: Influencer, PR & seeding | B25: £ | C25: =Assumptions!C61*C10 -> 264421 | D25: =Assumptions!D61*D10 -> 324560.46 | E25: =Assumptions!E61*E10 -> 374354.19 | F25: =Assumptions!F61*F10 -> 458975.75 | G25: =Assumptions!G61*G10 -> 465029.25
A26: Trade marketing & retail activation | B26: £ | C26: =Assumptions!C62*'Revenue Build'!C43 -> 44697.5 | D26: =Assumptions!D62*'Revenue Build'!D43 -> 73032.109 | E26: =Assumptions!E62*'Revenue Build'!E43 -> 100439.93 | F26: =Assumptions!F62*'Revenue Build'!F43 -> 137150.2 | G26: =Assumptions!G62*'Revenue Build'!G43 -> 151773.69
A27: Brand, content & creative | B27: £ | C27: =Assumptions!C63 -> 60000 | D27: =Assumptions!D63 -> 80000 | E27: =Assumptions!E63 -> 100000 | F27: =Assumptions!F63 -> 120000 | G27: =Assumptions!G63 -> 140000
A28: Payment processing fees | B28: £ | C28: =Assumptions!C64*'Revenue Build'!C42 -> 56930.5 | D28: =Assumptions!D64*'Revenue Build'!D42 -> 75503.12 | E28: =Assumptions!E64*'Revenue Build'!E42 -> 94824.622 | F28: =Assumptions!F64*'Revenue Build'!F42 -> 107902.1 | G28: =Assumptions!G64*'Revenue Build'!G42 -> 126725.1
A29: Sales commissions | B29: £ | C29: =Assumptions!C65*('Revenue Build'!C43+'Revenue Build'!C45) -> 15385.35 | D29: =Assumptions!D65*('Revenue Build'!D43+'Revenue Build'!D45) -> 25945.618 | E29: =Assumptions!E65*('Revenue Build'!E43+'Revenue Build'!E45) -> 41814.656 | F29: =Assumptions!F65*('Revenue Build'!F43+'Revenue Build'!F45) -> 59587.278 | G29: =Assumptions!G65*('Revenue Build'!G43+'Revenue Build'!G45) -> 76924.36
A30: Total marketing & selling | B30: £ | C30: =SUM(C24:C29) -> 970276.35 | D30: =SUM(D24:D29) -> 1228162.2 | E30: =SUM(E24:E29) -> 1460141.8 | F30: =SUM(F24:F29) -> 1725070.9 | G30: =SUM(G24:G29) -> 1890510.9
A31: Marketing & selling % of net revenue | B31: % | C31: =IFERROR(C30/C10,0) -> 0.29355501 | D31: =IFERROR(D30/D10,0) -> 0.26488549 | E31: =IFERROR(E30/E10,0) -> 0.23402572 | F31: =IFERROR(F30/F10,0) -> 0.22551137 | G31: =IFERROR(G30/G10,0) -> 0.20326796
A33: People costs
A34: Leadership | B34: £ | C34: =Assumptions!C68*Assumptions!$C$73*1*(1+Assumptions!C79) -> 212400 | D34: =Assumptions!D68*Assumptions!$C$73*(1+Assumptions!D78)*(1+Assumptions!D79) -> 219834 | E34: =Assumptions!E68*Assumptions!$C$73*(1+Assumptions!D78)*(1+Assumptions!E78)*(1+Assumptions!E79) -> 341292.28 | F34: =Assumptions!F68*Assumptions!$C$73*(1+Assumptions!D78)*(1+Assumptions!E78)*(1+Assumptions!F78)*(1+Assumptions!F79) -> 351531.05 | G34: =Assumptions!G68*Assumptions!$C$73*(1+Assumptions!D78)*(1+Assumptions!E78)*(1+Assumptions!F78)*(1+Assumptions!G78)*(1+Assumptions!G79) -> 362076.99
A35: Sales & Marketing | B35: £ | C35: =Assumptions!C69*Assumptions!$C$74*1*(1+Assumptions!C79) -> 159300 | D35: =Assumptions!D69*Assumptions!$C$74*(1+Assumptions!D78)*(1+Assumptions!D79) -> 274792.5 | E35: =Assumptions!E69*Assumptions!$C$74*(1+Assumptions!D78)*(1+Assumptions!E78)*(1+Assumptions!E79) -> 398174.33 | F35: =Assumptions!F69*Assumptions!$C$74*(1+Assumptions!D78)*(1+Assumptions!E78)*(1+Assumptions!F78)*(1+Assumptions!F79) -> 527296.58 | G35: =Assumptions!G69*Assumptions!$C$74*(1+Assumptions!D78)*(1+Assumptions!E78)*(1+Assumptions!F78)*(1+Assumptions!G78)*(1+Assumptions!G79) -> 663807.81
A36: Product Development & R&D | B36: £ | C36: =Assumptions!C70*Assumptions!$C$75*1*(1+Assumptions!C79) -> 59000 | D36: =Assumptions!D70*Assumptions!$C$75*(1+Assumptions!D78)*(1+Assumptions!D79) -> 122130 | E36: =Assumptions!E70*Assumptions!$C$75*(1+Assumptions!D78)*(1+Assumptions!E78)*(1+Assumptions!E79) -> 189606.83 | F36: =Assumptions!F70*Assumptions!$C$75*(1+Assumptions!D78)*(1+Assumptions!E78)*(1+Assumptions!F78)*(1+Assumptions!F79) -> 260393.37 | G36: =Assumptions!G70*Assumptions!$C$75*(1+Assumptions!D78)*(1+Assumptions!E78)*(1+Assumptions!F78)*(1+Assumptions!G78)*(1+Assumptions!G79) -> 268205.17
A37: Operations & Supply Chain | B37: £ | C37: =Assumptions!C71*Assumptions!$C$76*1*(1+Assumptions!C79) -> 47200 | D37: =Assumptions!D71*Assumptions!$C$76*(1+Assumptions!D78)*(1+Assumptions!D79) -> 97704 | E37: =Assumptions!E71*Assumptions!$C$76*(1+Assumptions!D78)*(1+Assumptions!E78)*(1+Assumptions!E79) -> 151685.46 | F37: =Assumptions!F71*Assumptions!$C$76*(1+Assumptions!D78)*(1+Assumptions!E78)*(1+Assumptions!F78)*(1+Assumptions!F79) -> 208314.7 | G37: =Assumptions!G71*Assumptions!$C$76*(1+Assumptions!D78)*(1+Assumptions!E78)*(1+Assumptions!F78)*(1+Assumptions!G78)*(1+Assumptions!G79) -> 268205.17
A38: Finance, HR & Admin | B38: £ | C38: =Assumptions!C72*Assumptions!$C$77*1*(1+Assumptions!C79) -> 49560 | D38: =Assumptions!D72*Assumptions!$C$77*(1+Assumptions!D78)*(1+Assumptions!D79) -> 51294.6 | E38: =Assumptions!E72*Assumptions!$C$77*(1+Assumptions!D78)*(1+Assumptions!E78)*(1+Assumptions!E79) -> 106179.82 | F38: =Assumptions!F72*Assumptions!$C$77*(1+Assumptions!D78)*(1+Assumptions!E78)*(1+Assumptions!F78)*(1+Assumptions!F79) -> 164047.82 | G38: =Assumptions!G72*Assumptions!$C$77*(1+Assumptions!D78)*(1+Assumptions!E78)*(1+Assumptions!F78)*(1+Assumptions!G78)*(1+Assumptions!G79) -> 168969.26
A39: Contractors & freelancers | B39: £ | C39: =Assumptions!C80 -> 40000 | D39: =Assumptions!D80 -> 50000 | E39: =Assumptions!E80 -> 60000 | F39: =Assumptions!F80 -> 70000 | G39: =Assumptions!G80 -> 80000
A40: Total people costs | B40: £ | C40: =SUM(C34:C39) -> 567460 | D40: =SUM(D34:D39) -> 815755.1 | E40: =SUM(E34:E39) -> 1246938.7 | F40: =SUM(F34:F39) -> 1581583.5 | G40: =SUM(G34:G39) -> 1811264.4
A41: Total headcount (FTE) | B41: FTE | C41: =SUM(Assumptions!C68:C72) -> 8 | D41: =SUM(Assumptions!D68:D72) -> 12 | E41: =SUM(Assumptions!E68:E72) -> 18 | F41: =SUM(Assumptions!F68:F72) -> 23 | G41: =SUM(Assumptions!G68:G72) -> 26
A43: Other operating expenses
A44: Product development & testing | B44: £ | C44: =Assumptions!C83 -> 50000 | D44: =Assumptions!D83 -> 70000 | E44: =Assumptions!E83 -> 90000 | F44: =Assumptions!F83 -> 110000 | G44: =Assumptions!G83 -> 130000
A45: Regulatory & compliance | B45: £ | C45: =Assumptions!C84 -> 25000 | D45: =Assumptions!D84 -> 30000 | E45: =Assumptions!E84 -> 40000 | F45: =Assumptions!F84 -> 45000 | G45: =Assumptions!G84 -> 50000
A46: Rent & facilities | B46: £ | C46: =Assumptions!C85 -> 30000 | D46: =Assumptions!D85 -> 40000 | E46: =Assumptions!E85 -> 60000 | F46: =Assumptions!F85 -> 60000 | G46: =Assumptions!G85 -> 80000
...
